Workbook

Sheet Prenatal Phases
A1: Phase | B1: Weeks | C1: Biological Focus | D1: Activation % | E1: DNA Trigger | F1: Next Phase Condition
A2: 1 | B2: 0–4 | C2: Embryogenesis | D2: 0–10% | E2: DNA_INIT | F2: Neural plate formed
A3: 2 | B3: 4–8 | C3: Organogenesis | D3: 10–25% | E3: ORG_START | F3: Limb buds visible
A4: 3 | B4: 8–12 | C4: Body Plan | D4: 25–40% | E4: BODY_FORM | F4: Reflex seed active
A5: 4 | B5: 12–20 | C5: Reflex Explosion | D5: 40–60% | E5: REFLEX_ON | F5: Stretch reflex stable
A6: 5 | B6: 20–28 | C6: Neural Maturation | D6: 60–80% | E6: NEURAL_GROW | F6: Predictive circuits online
A7: 6 | B7: 28–36 | C7: Pre‑Birth Integration | D7: 80–95% | E7: INTEGRATE | F7: Reflexes synchronised
A8: 7 | B8: 36–40 | C8: Birth Preparation | D8: 95–100% | E8: BIRTH_READY | F8: Lungs mature

Sheet Anatomy Growth Engine
A1: Name | B1: Category | C1: DNA Code | D1: Start Week | E1: End Week | F1: Growth Curve | G1: Domain | H1: Current Week | I1: Growth Status | J1: Activation % | K1: Parent | L1: Local X | M1: Local Y | N1: Local Z | O1: Connection Type | P1: Dynamic X | Q1: Dynamic Y | R1: Dynamic Z | S1: Tension Vector | T1: Tension Magnitude | U1: Tension Status
A2: Frontal Bone | B2: Skeleton | C2: SK_FRONTAL | D2: 4 | E2: 36 | F2: Sigmoid | G2: Embodiment | H2: ='DNA Loop Engine'!$B$5 -> 50 | I2: =IF(H2<D2,"⏳ Pending",IF(H2>=E2,"✅ Complete","🔄 Growing")) -> ✅ Complete | J2: =IF(H2<D2,0,IF(H2>=E2,1,(H2-D2)/(E2-D2))) -> 1 | K2: Point 0 | L2: 0 | M2: 0.85 | N2: 0.08 | O2: Suture | P2: =L2*J2 -> 0 | Q2: =M2*J2 -> 0.85 | R2: =N2*J2 -> 0.08
A3: Parietal Bone (Left) | B3: Skeleton | C3: SK_PAR_L | D3: 4 | E3: 36 | F3: Sigmoid | G3: Embodiment | H3: ='DNA Loop Engine'!$B$5 -> 50 | I3: =IF(H3<D3,"⏳ Pending",IF(H3>=E3,"✅ Complete","🔄 Growing")) -> ✅ Complete | J3: =IF(H3<D3,0,IF(H3>=E3,1,(H3-D3)/(E3-D3))) -> 1 | K3: Point 0 | L3: -0.08 | M3: 0.88 | N3: 0 | O3: Suture | P3: =L3*J3 -> -0.08 | Q3: =M3*J3 -> 0.88 | R3: =N3*J3 -> 0
A4: Parietal Bone (Right) | B4: Skeleton | C4: SK_PAR_R | D4: 4 | E4: 36 | F4: Sigmoid | G4: Embodiment | H4: ='DNA Loop Engine'!$B$5 -> 50 | I4: =IF(H4<D4,"⏳ Pending",IF(H4>=E4,"✅ Complete","🔄 Growing")) -> ✅ Complete | J4: =IF(H4<D4,0,IF(H4>=E4,1,(H4-D4)/(E4-D4))) -> 1 | K4: Point 0 | L4: 0.08 | M4: 0.88 | N4: 0 | O4: Suture | P4: =L4*J4 -> 0.08 | Q4: =M4*J4 -> 0.88 | R4: =N4*J4 -> 0
A5: Temporal Bone (Left) | B5: Skeleton | C5: SK_TEMP_L | D5: 4 | E5: 36 | F5: Sigmoid | G5: Embodiment | H5: ='DNA Loop Engine'!$B$5 -> 50 | I5: =IF(H5<D5,"⏳ Pending",IF(H5>=E5,"✅ Complete","🔄 Growing")) -> ✅ Complete | J5: =IF(H5<D5,0,IF(H5>=E5,1,(H5-D5)/(E5-D5))) -> 1 | K5: Point 0 | L5: -0.12 | M5: 0.82 | N5: -0.02 | O5: Suture | P5: =L5*J5 -> -0.12 | Q5: =M5*J5 -> 0.82 | R5: =N5*J5 -> -0.02
A6: Temporal Bone (Right) | B6: Skeleton | C6: SK_TEMP_R | D6: 4 | E6: 36 | F6: Sigmoid | G6: Embodiment | H6: ='DNA Loop Engine'!$B$5 -> 50 | I6: =IF(H6<D6,"⏳ Pending",IF(H6>=E6,"✅ Complete","🔄 Growing")) -> ✅ Complete | J6: =IF(H6<D6,0,IF(H6>=E6,1,(H6-D6)/(E6-D6))) -> 1 | K6: Point 0 | L6: 0.12 | M6: 0.82 | N6: -0.02 | O6: Suture | P6: =L6*J6 -> 0.12 | Q6: =M6*J6 -> 0.82 | R6: =N6*J6 -> -0.02
A7: Occipital Bone | B7: Skeleton | C7: SK_OCCIPITAL | D7: 4 | E7: 36 | F7: Sigmoid | G7: Embodiment | H7: ='DNA Loop Engine'!$B$5 -> 50 | I7: =IF(H7<D7,"⏳ Pending",IF(H7>=E7,"✅ Complete","🔄 Growing")) -> ✅ Complete | J7: =IF(H7<D7,0,IF(H7>=E7,1,(H7-D7)/(E7-D7))) -> 1 | K7: Point 0 | L7: 0 | M7: 0.8 | N7: -0.08 | O7: Suture | P7: =L7*J7 -> 0 | Q7: =M7*J7 -> 0.8 | R7: =N7*J7 -> -0.08
A8: Sphenoid Bone | B8: Skeleton | C8: SK_SPHENOID | D8: 4 | E8: 36 | F8: Sigmoid | G8: Embodiment | H8: ='DNA Loop Engine'!$B$5 -> 50 | I8: =IF(H8<D8,"⏳ Pending",IF(H8>=E8,"✅ Complete","🔄 Growing")) -> ✅ Complete | J8: =IF(H8<D8,0,IF(H8>=E8,1,(H8-D8)/(E8-D8))) -> 1 | K8: Point 0 | L8: 0 | M8: 0.78 | N8: 0.02 | O8: Suture | P8: =L8*J8 -> 0 | Q8: =M8*J8 -> 0.78 | R8: =N8*J8 -> 0.02
A9: Ethmoid Bone | B9: Skeleton | C9: SK_ETHMOID | D9: 4 | E9: 36 | F9: Sigmoid | G9: Embodiment | H9: ='DNA Loop Engine'!$B$5 -> 50 | I9: =IF(H9<D9,"⏳ Pending",IF(H9>=E9,"✅ Complete","🔄 Growing")) -> ✅ Complete | J9: =IF(H9<D9,0,IF(H9>=E9,1,(H9-D9)/(E9-D9))) -> 1 | K9: Point 0 | L9: 0 | M9: 0.8 | N9: 0.04 | O9: Suture | P9: =L9*J9 -> 0 | Q9: =M9*J9 -> 0.8 | R9: =N9*J9 -> 0.04
A10: Nasal Bone (Left) | B10: Skeleton | C10: SK_NASAL_L | D10: 5 | E10: 20 | F10: Sigmoid | G10: Embodiment | H10: ='DNA Loop Engine'!$B$5 -> 50 | I10: =IF(H10<D10,"⏳ Pending",IF(H10>=E10,"✅ Complete","🔄 Growing")) -> ✅ Complete | J10: =IF(H10<D10,0,IF(H10>=E10,1,(H10-D10)/(E10-D10))) -> 1 | K10: Frontal Bone | L10: -0.02 | M10: 0.75 | N10: 0.1 | O10: Suture | P10: =L10*J10 -> -0.02 | Q10: =M10*J10 -> 0.75 | R10: =N10*J10 -> 0.1
A11: Nasal Bone (Right) | B11: Skeleton | C11: SK_NASAL_R | D11: 5 | E11: 20 | F11: Sigmoid | G11: Embodiment | H11: ='DNA Loop Engine'!$B$5 -> 50 | I11: =IF(H11<D11,"⏳ Pending",IF(H11>=E11,"✅ Complete","🔄 Growing")) -> ✅ Complete | J11: =IF(H11<D11,0,IF(H11>=E11,1,(H11-D11)/(E11-D11))) -> 1 | K11: Frontal Bone | L11: 0.02 | M11: 0.75 | N11: 0.1 | O11: Suture | P11: =L11*J11 -> 0.02 | Q11: =M11*J11 -> 0.75 | R11: =N11*J11 -> 0.1
A12: Lacrimal Bone (Left) | B12: Skeleton | C12: SK_LACRIMAL_L | D12: 5 | E12: 20 | F12: Sigmoid | G12: Embodiment | H12: ='DNA Loop Engine'!$B$5 -> 50 | I12: =IF(H12<D12,"⏳ Pending",IF(H12>=E12,"✅ Complete","🔄 Growing")) -> ✅ Complete | J12: =IF(H12<D12,0,IF(H12>=E12,1,(H12-D12)/(E12-D12))) -> 1 | K12: Frontal Bone | L12: -0.03 | M12: 0.76 | N12: 0.08 | O12: Suture | P12: =L12*J12 -> -0.03 | Q12: =M12*J12 -> 0.76 | R12: =N12*J12 -> 0.08
A13: Lacrimal Bone (Right) | B13: Skeleton | C13: SK_LACRIMAL_R | D13: 5 | E13: 20 | F13: Sigmoid | G13: Embodiment | H13: ='DNA Loop Engine'!$B$5 -> 50 | I13: =IF(H13<D13,"⏳ Pending",IF(H13>=E13,"✅ Complete","🔄 Growing")) -> ✅ Complete | J13: =IF(H13<D13,0,IF(H13>=E13,1,(H13-D13)/(E13-D13))) -> 1 | K13: Frontal Bone | L13: 0.03 | M13: 0.76 | N13: 0.08 | O13: Suture | P13: =L13*J13 -> 0.03 | Q13: =M13*J13 -> 0.76 | R13: =N13*J13 -> 0.08
... A159: Biceps Femoris | B159: Muscle | C159: MS_BIC_FEM | D159: 8 | E159: 36 | F159: Sigmoid | G159: Motor Control | H159: ='DNA Loop Engine'!$B$5 -> 50 | I159: =IF(H159<D159,"⏳ Pending",IF(H159>=E159,"✅ Complete","🔄 Growing")) -> ✅ Complete | J159: =IF(H159<D159,0,IF(H159>=E159,1,(H159-D159)/(E159-D159))) -> 1 | K159: Hip Bone (Left) | L159: -0.14 | M159: -0.24 | N159: -0.02 | O159: Tendon | P159: =L159*J159 -> -0.14 | Q159: =M159*J159 -> -0.24 | R159: =N159*J159 -> -0.02
A160: Patellar Tendon | B160: Connective | C160: CT_PAT_TEND | D160: 8 | E160: 36 | F160: Sigmoid | G160: Embodiment | H160: ='DNA Loop Engine'!$B$5 -> 50 | I160: =IF(H160<D160,"⏳ Pending",IF(H160>=E160,"✅ Complete","🔄 Growing")) -> ✅ Complete | J160: =IF(H160<D160,0,IF(H160>=E160,1,MIN(1,(H160-D160)/(E160-D160)))) -> 1 | K160: Femur (Left) | L160: -0.15 | M160: -0.8 | N160: 0 | O160: Tendon | P160: =L160*J160 -> -0.15 | Q160: =M160*J160 -> -0.8 | R160: =N160*J160 -> 0 | S160: ="("&TEXT(P160,"0.00")&", "&TEXT(Q160,"0.00")&", "&TEXT(R160,"0.00")&")" -> (-0.15, -0.80, 0.00) | T160: =SQRT(P160^2+Q160^2+R160^2)*(1+'DNA Loop Engine'!B18) -> 1.6278821 | U160: =IF(T160<0.5,"🟢 Relaxed",IF(T160<1,"🟡 Normal",IF(T160<1.5,"🟠 Taut","🔴 Stressed"))) -> 🔴 Stressed
A161: Achilles Tendon | B161: Connective | C161: CT_ACH_TEND | D161: 8 | E161: 36 | F161: Sigmoid | G161: Embodiment | H161: ='DNA Loop Engine'!$B$5 -> 50 | I161: =IF(H161<D161,"⏳ Pending",IF(H161>=E161,"✅ Complete","🔄 Growing")) -> ✅ Complete | J161: =IF(H161<D161,0,IF(H161>=E161,1,MIN(1,(H161-D161)/(E161-D161)))) -> 1 | K161: Tibia (Left) | L161: -0.15 | M161: -1.1 | N161: 0 | O161: Tendon | P161: =L161*J161 -> -0.15 | Q161: =M161*J161 -> -1.1 | R161: =N161*J161 -> 0 | S161: ="("&TEXT(P161,"0.00")&", "&TEXT(Q161,"0.00")&", "&TEXT(R161,"0.00")&")" -> (-0.15, -1.10, 0.00) | T161: =SQRT(P161^2+Q161^2+R161^2)*(1+'DNA Loop Engine'!B18) -> 2.2203603 | U161: =IF(T161<0.5,"🟢 Relaxed",IF(T161<1,"🟡 Normal",IF(T161<1.5,"🟠 Taut","🔴 Stressed"))) -> 🔴 Stressed
A162: Biceps Tendon | B162: Connective | C162: CT_BIC_TEND | D162: 8 | E162: 36 | F162: Sigmoid | G162: Embodiment | H162: ='DNA Loop Engine'!$B$5 -> 50 | I162: =IF(H162<D162,"⏳ Pending",IF(H162>=E162,"✅ Complete","🔄 Growing")) -> ✅ Complete | J162: =IF(H162<D162,0,IF(H162>=E162,1,MIN(1,(H162-D162)/(E162-D162)))) -> 1 | K162: Scapula (Left) | L162: -0.25 | M162: 0.4 | N162: 0 | O162: Tendon | P162: =L162*J162 -> -0.25 | Q162: =M162*J162 -> 0.4 | R162: =N162*J162 -> 0 | S162: ="("&TEXT(P162,"0.00")&", "&TEXT(Q162,"0.00")&", "&TEXT(R162,"0.00")&")" -> (-0.25, 0.40, 0.00) | T162: =SQRT(P162^2+Q162^2+R162^2)*(1+'DNA Loop Engine'!B18) -> 0.94339811 | U162: =IF(T162<0.5,"🟢 Relaxed",IF(T162<1,"🟡 Normal",IF(T162<1.5,"🟠 Taut","🔴 Stressed"))) -> 🟡 Normal
A163: Triceps Tendon | B163: Connective | C163: CT_TRI_TEND | D163: 8 | E163: 36 | F163: Sigmoid | G163: Embodiment | H163: ='DNA Loop Engine'!$B$5 -> 50 | I163: =IF(H163<D163,"⏳ Pending",IF(H163>=E163,"✅ Complete","🔄 Growing")) -> ✅ Complete | J163: =IF(H163<D163,0,IF(H163>=E163,1,MIN(1,(H163-D163)/(E163-D163)))) -> 1 | K163: Humerus (Left) | L163: -0.25 | M163: 0.7 | N163: 0 | O163: Tendon | P163: =L163*J163 -> -0.25 | Q163: =M163*J163 -> 0.7 | R163: =N163*J163 -> 0 | S163: ="("&TEXT(P163,"0.00")&", "&TEXT(Q163,"0.00")&", "&TEXT(R163,"0.00")&")" -> (-0.25, 0.70, 0.00) | T163: =SQRT(P163^2+Q163^2+R163^2)*(1+'DNA Loop Engine'!B18) -> 1.4866069 | U163: =IF(T163<0.5,"🟢 Relaxed",IF(T163<1,"🟡 Normal",IF(T163<1.5,"🟠 Taut","🔴 Stressed"))) -> 🟠 Taut
A164: Rotator Cuff Tendons | B164: Connective | C164: CT_ROT_CUFF | D164: 8 | E164: 36 | F164: Sigmoid | G164: Embodiment | H164: ='DNA Loop Engine'!$B$5 -> 50 | I164: =IF(H164<D164,"⏳ Pending",IF(H164>=E164,"✅ Complete","🔄 Growing")) -> ✅ Complete | J164: =IF(H164<D164,0,IF(H164>=E164,1,MIN(1,(H164-D164)/(E164-D164)))) -> 1 | K164: Scapula (Left) | L164: -0.25 | M164: 0.4 | N164: 0 | O164: Tendon | P164: =L164*J164 -> -0.25 | Q164: =M164*J164 -> 0.4 | R164: =N164*J164 -> 0 | S164: ="("&TEXT(P164,"0.00")&", "&TEXT(Q164,"0.00")&", "&TEXT(R164,"0.00")&")" -> (-0.25, 0.40, 0.00) | T164: =SQRT(P164^2+Q164^2+R164^2)*(1+'DNA Loop Engine'!B18) -> 0.94339811 | U164: =IF(T164<0.5,"🟢 Relaxed",IF(T164<1,"🟡 Normal",IF(T164<1.5,"🟠 Taut","🔴 Stressed"))) -> 🟡 Normal
A165: Anterior Cruciate Ligament | B165: Connective | C165: CT_ACL | D165: 8 | E165: 36 | F165: Sigmoid | G165: Embodiment | H165: ='DNA Loop Engine'!$B$5 -> 50 | I165: =IF(H165<D165,"⏳ Pending",IF(H165>=E165,"✅ Complete","🔄 Growing")) -> ✅ Complete | J165: =IF(H165<D165,0,IF(H165>=E165,1,MIN(1,(H165-D165)/(E165-D165)))) -> 1 | K165: Femur (Left) | L165: -0.15 | M165: -0.8 | N165: 0 | O165: Ligament | P165: =L165*J165 -> -0.15 | Q165: =M165*J165 -> -0.8 | R165: =N165*J165 -> 0 | S165: ="("&TEXT(P165,"0.00")&", "&TEXT(Q165,"0.00")&", "&TEXT(R165,"0.00")&")" -> (-0.15, -0.80, 0.00) | T165: =SQRT(P165^2+Q165^2+R165^2)*(1+'DNA Loop Engine'!B18) -> 1.6278821 | U165: =IF(T165<0.5,"🟢 Relaxed",IF(T165<1,"🟡 Normal",IF(T165<1.5,"🟠 Taut","🔴 Stressed"))) -> 🔴 Stressed
A166: Posterior Cruciate Ligament | B166: Connective | C166: CT_PCL | D166: 8 | E166: 36 | F166: Sigmoid | G166: Embodiment | H166: ='DNA Loop Engine'!$B$5 -> 50 | I166: =IF(H166<D166,"⏳ Pending",IF(H166>=E166,"✅ Complete","🔄 Growing")) -> ✅ Complete | J166: =IF(H166<D166,0,IF(H166>=E166,1,MIN(1,(H166-D166)/(E166-D166)))) -> 1 | K166: Femur (Left) | L166: -0.15 | M166: -0.8 | N166: 0 | O166: Ligament | P166: =L166*J166 -> -0.15 | Q166: =M166*J166 -> -0.8 | R166: =N166*J166 -> 0 | S166: ="("&TEXT(P166,"0.00")&", "&TEXT(Q166,"0.00")&", "&TEXT(R166,"0.00")&")" -> (-0.15, -0.80, 0.00) | T166: =SQRT(P166^2+Q166^2+R166^2)*(1+'DNA Loop Engine'!B18) -> 1.6278821 | U166: =IF(T166<0.5,"🟢 Relaxed",IF(T166<1,"🟡 Normal",IF(T166<1.5,"🟠 Taut","🔴 Stressed"))) -> 🔴 Stressed
A167: Medial Collateral Ligament | B167: Connective | C167: CT_MCL | D167: 8 | E167: 36 | F167: Sigmoid | G167: Embodiment | H167: ='DNA Loop Engine'!$B$5 -> 50 | I167: =IF(H167<D167,"⏳ Pending",IF(H167>=E167,"✅ Complete","🔄 Growing")) -> ✅ Complete | J167: =IF(H167<D167,0,IF(H167>=E167,1,MIN(1,(H167-D167)/(E167-D167)))) -> 1 | K167: Femur (Left) | L167: -0.12 | M167: -0.8 | N167: 0 | O167: Ligament | P167: =L167*J167 -> -0.12 | Q167: =M167*J167 -> -0.8 | R167: =N167*J167 -> 0 | S167: ="("&TEXT(P167,"0.00")&", "&TEXT(Q167,"0.00")&", "&TEXT(R167,"0.00")&")" -> (-0.12, -0.80, 0.00) | T167: =SQRT(P167^2+Q167^2+R167^2)*(1+'DNA Loop Engine'!B18) -> 1.6178999 | U167: =IF(T167<0.5,"🟢 Relaxed",IF(T167<1,"🟡 Normal",IF(T167<1.5,"🟠 Taut","🔴 Stressed"))) -> 🔴 Stressed
A168: Lateral Collateral Ligament | B168: Connective | C168: CT_LCL | D168: 8 | E168: 36 | F168: Sigmoid | G168: Embodiment | H168: ='DNA Loop Engine'!$B$5 -> 50 | I168: =IF(H168<D168,"⏳ Pending",IF(H168>=E168,"✅ Complete","🔄 Growing")) -> ✅ Complete | J168: =IF(H168<D168,0,IF(H168>=E168,1,MIN(1,(H168-D168)/(E168-D168)))) -> 1 | K168: Femur (Left) | L168: -0.18 | M168: -0.8 | N168: 0 | O168: Ligament | P168: =L168*J168 -> -0.18 | Q168: =M168*J168 -> -0.8 | R168: =N168*J168 -> 0 | S168: ="("&TEXT(P168,"0.00")&", "&TEXT(Q168,"0.00")&", "&TEXT(R168,"0.00")&")" -> (-0.18, -0.80, 0.00) | T168: =SQRT(P168^2+Q168^2+R168^2)*(1+'DNA Loop Engine'!B18) -> 1.64 | U168: =IF(T168<0.5,"🟢 Relaxed",IF(T168<1,"🟡 Normal",IF(T168<1.5,"🟠 Taut","🔴 Stressed"))) -> 🔴 Stressed
A169: Interspinous Ligament | B169: Connective | C169: CT_INTERSPIN | D169: 8 | E169: 36 | F169: Sigmoid | G169: Embodiment | H169: ='DNA Loop Engine'!$B$5 -> 50 | I169: =IF(H169<D169,"⏳ Pending",IF(H169>=E169,"✅ Complete","🔄 Growing")) -> ✅ Complete | J169: =IF(H169<D169,0,IF(H169>=E169,1,MIN(1,(H169-D169)/(E169-D169)))) -> 1 | K169: Thoracic Vertebrae (T1–T12) | L169: 0 | M169: 0.4 | N169: -0.06 | O169: Ligament | P169: =L169*J169 -> 0 | Q169: =M169*J169 -> 0.4 | R169: =N169*J169 -> -0.06 | S169: ="("&TEXT(P169,"0.00")&", "&TEXT(Q169,"0.00")&", "&TEXT(R169,"0.00")&")" -> (0.00, 0.40, -0.06) | T169: =SQRT(P169^2+Q169^2+R169^2)*(1+'DNA Loop Engine'!B18) -> 0.80894994 | U169: =IF(T169<0.5,"🟢 Relaxed",IF(T169<1,"🟡 Normal",IF(T169<1.5,"🟠 Taut","🔴 Stressed"))) -> 🟡 Normal
A170: Glenohumeral Ligament | B170: Connective | C170: CT_GLENOHUM | D170: 8 | E170: 36 | F170: Sigmoid | G170: Embodiment | H170: ='DNA Loop Engine'!$B$5 -> 50 | I170: =IF(H170<D170,"⏳ Pending",IF(H170>=E170,"✅ Complete","🔄 Growing")) -> ✅ Complete | J170: =IF(H170<D170,0,IF(H170>=E170,1,MIN(1,(H170-D170)/(E170-D170)))) -> 1 | K170: Scapula (Left) | L170: -0.25 | M170: 0.4 | N170: 0 | O170: Ligament | P170: =L170*J170 -> -0.25 | Q170: =M170*J170 -> 0.4 | R170: =N170*J170 -> 0 | S170: ="("&TEXT(P170,"0.00")&", "&TEXT(Q170,"0.00")&", "&TEXT(R170,"0.00")&")" -> (-0.25, 0.40, 0.00) | T170: =SQRT(P170^2+Q170^2+R170^2)*(1+'DNA Loop Engine'!B18) -> 0.94339811 | U170: =IF(T170<0.5,"🟢 Relaxed",IF(T170<1,"🟡 Normal",IF(T170<1.5,"🟠 Taut","🔴 Stressed"))) -> 🟡 Normal
A171: Iliofemoral Ligament | B171: Connective | C171: CT_ILIOFEM | D171: 8 | E171: 36 | F171: Sigmoid | G171: Embodiment | H171: ='DNA Loop Engine'!$B$5 -> 50 | I171: =IF(H171<D171,"⏳ Pending",IF(H171>=E171,"✅ Complete","🔄 Growing")) -> ✅ Complete | J171: =IF(H171<D171,0,IF(H171>=E171,1,MIN(1,(H171-D171)/(E171-D171)))) -> 1 | K171: Hip Bone (Left) | L171: -0.15 | M171: -0.1 | N171: 0 | O171: Ligament | P171: =L171*J171 -> -0.15 | Q171: =M171*J171 -> -0.1 | R171: =N171*J171 -> 0 | S171: ="("&TEXT(P171,"0.00")&", "&TEXT(Q171,"0.00")&", "&TEXT(R171,"0.00")&")" -> (-0.15, -0.10, 0.00) | T171: =SQRT(P171^2+Q171^2+R171^2)*(1+'DNA Loop Engine'!B18) -> 0.36055513 | U171: =IF(T171<0.5,"🟢 Relaxed",IF(T171<1,"🟡 Normal",IF(T171<1.5,"🟠 Taut","🔴 Stressed"))) -> 🟢 Relaxed
A172: Pubofemoral Ligament | B172: Connective | C172: CT_PUBOFEM | D172: 8 | E172: 36 | F172: Sigmoid | G172: Embodiment | H172: ='DNA Loop Engine'!$B$5 -> 50 | I172: =IF(H172<D172,"⏳ Pending",IF(H172>=E172,"✅ Complete","🔄 Growing")) -> ✅ Complete | J172: =IF(H172<D172,0,IF(H172>=E172,1,MIN(1,(H172-D172)/(E172-D172)))) -> 1 | K172: Hip Bone (Left) | L172: -0.12 | M172: -0.08 | N172: 0 | O172: Ligament | P172: =L172*J172 -> -0.12 | Q172: =M172*J172 -> -0.08 | R172: =N172*J172 -> 0 | S172: ="("&TEXT(P172,"0.00")&", "&TEXT(Q172,"0.00")&", "&TEXT(R172,"0.00")&")" -> (-0.12, -0.08, 0.00) | T172: =SQRT(P172^2+Q172^2+R172^2)*(1+'DNA Loop Engine'!B18) -> 0.2884441 | U172: =IF(T172<0.5,"🟢 Relaxed",IF(T172<1,"🟡 Normal",IF(T172<1.5,"🟠 Taut","🔴 Stressed"))) -> 🟢 Relaxed
A173: Ischiofemoral Ligament | B173: Connective | C173: CT_ISCHIOFEM | D173: 8 | E173: 36 | F173: Sigmoid | G173: Embodiment | H173: ='DNA Loop Engine'!$B$5 -> 50 | I173: =IF(H173<D173,"⏳ Pending",IF(H173>=E173,"✅ Complete","🔄 Growing")) -> ✅ Complete | J173: =IF(H173<D173,0,IF(H173>=E173,1,MIN(1,(H173-D173)/(E173-D173)))) -> 1 | K173: Hip Bone (Left) | L173: -0.14 | M173: -0.12 | N173: -0.02 | O173: Ligament | P173: =L173*J173 -> -0.14 | Q173: =M173*J173 -> -0.12 | R173: =N173*J173 -> -0.02 | S173: ="("&TEXT(P173,"0.00")&", "&TEXT(Q173,"0.00")&", "&TEXT(R173,"0.00")&")" -> (-0.14, -0.12, -0.02) | T173: =SQRT(P173^2+Q173^2+R173^2)*(1+'DNA Loop Engine'!B18) -> 0.37094474 | U173: =IF(T173<0.5,"🟢 Relaxed",IF(T173<1,"🟡 Normal",IF(T173<1.5,"🟠 Taut","🔴 Stressed"))) -> 🟢 Relaxed
A175: 🧠 NEURAL CONTROL MAPPING TABLE
A176: Name | B176: Controlled Structure | C176: Neural Region | D176: Control Type | E176: Signal Pathway | F176: Feedback Source | G176: Activation Week | H176: Full Maturity Week | I176: Domain | J176: Current Week | K176: Neural Status | L176: Maturity %
A177: Motor Cortex | B177: Hip Joint (L/R) | C177: Cortical Motor | D177: Voluntary | E177: Descending Corticospinal | F177: Muscle Spindles | G177: 20 | H177: 36 | I177: Motor Control | J177: ='DNA Loop Engine'!$B$5 -> 50 | K177: =IF(J177<G177,"⏳ Dormant",IF(J177>=H177,"✅ Mature","🔄 Developing")) -> ✅ Mature | L177: =IF(J177<G177,0%,IF(J177>=H177,100%,(J177-G177)/(H177-G177))) -> 1
A178: Motor Cortex | B178: Shoulder Joint (L/R) | C178: Cortical Motor | D178: Voluntary | E178: Descending Corticospinal | F178: Muscle Spindles | G178: 20 | H178: 36 | I178: Motor Control | J178: ='DNA Loop Engine'!$B$5 -> 50 | K178: =IF(J178<G178,"⏳ Dormant",IF(J178>=H178,"✅ Mature","🔄 Developing")) -> ✅ Mature | L178: =IF(J178<G178,0%,IF(J178>=H178,100%,(J178-G178)/(H178-G178))) -> 1
A179: Motor Cortex | B179: Elbow Joint (L/R) | C179: Cortical Motor | D179: Voluntary | E179: Descending Corticospinal | F179: Muscle Spindles | G179: 20 | H179: 36 | I179: Motor Control | J179: ='DNA Loop Engine'!$B$5 -> 50 | K179: =IF(J179<G179,"⏳ Dormant",IF(J179>=H179,"✅ Mature","🔄 Developing")) -> ✅ Mature | L179: =IF(J179<G179,0%,IF(J179>=H179,100%,(J179-G179)/(H179-G179))) -> 1
A180: Motor Cortex | B180: Wrist Joint (L/R) | C180: Cortical Motor | D180: Voluntary | E180: Descending Corticospinal | F180: Muscle Spindles | G180: 20 | H180: 36 | I180: Motor Control | J180: ='DNA Loop Engine'!$B$5 -> 50 | K180: =IF(J180<G180,"⏳ Dormant",IF(J180>=H180,"✅ Mature","🔄 Developing")) -> ✅ Mature | L180: =IF(J180<G180,0%,IF(J180>=H180,100%,(J180-G180)/(H180-G180))) -> 1
A181: Cerebellum | B181: Ankle Joint (L/R) | C181: Subcortical Motor | D181: Coordinative | E181: Cerebellar Feedback | F181: Joint Receptors | G181: 24 | H181: 36 | I181: Motor Control | J181: ='DNA Loop Engine'!$B$5 -> 50 | K181: =IF(J181<G181,"⏳ Dormant",IF(J181>=H181,"✅ Mature","🔄 Developing")) -> ✅ Mature | L181: =IF(J181<G181,0%,IF(J181>=H181,100%,(J181-G181)/(H181-G181))) -> 1
A182: Cerebellum | B182: Spinal Segments | C182: Subcortical Motor | D182: Stabilisation | E182: Cerebellar Feedback | F182: Proprioceptors | G182: 24 | H182: 36 | I182: Motor Control | J182: ='DNA Loop Engine'!$B$5 -> 50 | K182: =IF(J182<G182,"⏳ Dormant",IF(J182>=H182,"✅ Mature","🔄 Developing")) -> ✅ Mature | L182: =IF(J182<G182,0%,IF(J182>=H182,100%,(J182-G182)/(H182-G182))) -> 1
A183: Brainstem | B183: Jaw Joint | C183: Autonomic | D183: Reflexive | E183: Trigeminal Pathway | F183: Stretch Receptors | G183: 12 | H183: 28 | I183: Reflexes | J183: ='DNA Loop Engine'!$B$5 -> 50 | K183: =IF(J183<G183,"⏳ Dormant",IF(J183>=H183,"✅ Mature","🔄 Developing")) -> ✅ Mature | L183: =IF(J183<G183,0%,IF(J183>=H183,100%,(J183-G183)/(H183-G183))) -> 1
A184: Brainstem | B184: Neck Joint | C184: Autonomic | D184: Reflexive | E184: Vestibulospinal Pathway | F184: Vestibular Apparatus | G184: 12 | H184: 28 | I184: Reflexes | J184: ='DNA Loop Engine'!$B$5 -> 50 | K184: =IF(J184<G184,"⏳ Dormant",IF(J184>=H184,"✅ Mature","🔄 Developing")) -> ✅ Mature | L184: =IF(J184<G184,0%,IF(J184>=H184,100%,(J184-G184)/(H184-G184))) -> 1
A185: Spinal Cord | B185: Knee Joint (L/R) | C185: Segmental | D185: Reflexive | E185: Spinal Reflex Arc | F185: Muscle Spindles | G185: 12 | H185: 20 | I185: Reflexes | J185: ='DNA Loop Engine'!$B$5 -> 50 | K185: =IF(J185<G185,"⏳ Dormant",IF(J185>=H185,"✅ Mature","🔄 Developing")) -> ✅ Mature | L185: =IF(J185<G185,0%,IF(J185>=H185,100%,(J185-G185)/(H185-G185))) -> 1
A186: Spinal Cord | B186: Elbow Joint (L/R) | C186: Segmental | D186: Reflexive | E186: Spinal Reflex Arc | F186: Muscle Spindles | G186: 12 | H186: 20 | I186: Reflexes | J186: ='DNA Loop Engine'!$B$5 -> 50 | K186: =IF(J186<G186,"⏳ Dormant",IF(J186>=H186,"✅ Mature","🔄 Developing")) -> ✅ Mature | L186: =IF(J186<G186,0%,IF(J186>=H186,100%,(J186-G186)/(H186-G186))) -> 1
...

Sheet Organ & System Activation
A1: an | B1: Organ/System | C1: Activation Event | D1: DNA Code | E1: Notes
A2: 0–4 | B2: Neural Plate | C2: Formation | D2: NP_FORM | E2: Primitive streak defines axes
A3: 4–8 | B3: Heart | C3: Chamber partition | D3: HT_PART | E3: First rhythmic contractions
A4: 8–12 | B4: Limbs | C4: Differentiation | D4: LM_DIFF | E4: Fingers/toes separate
A5: 12–20 | B5: Reflex Arcs | C5: Activation | D5: RF_ACT | E5: Stretch reflex online
A6: 20–28 | B6: Cerebellum | C6: Growth | D6: CB_GROW | E6: Predictive control begins
A7: 28–36 | B7: Myelination | C7: Neural insulation | D7: MYEL_ON | E7: Faster reflex transmission
A8: 36–40 | B8: Lungs | C8: Maturation | D8: LG_MAT | E8: Ready for external oxygen

Sheet Tick-Based DNA Loop
A1: Tick ID | B1: Week | C1: DNA Phase | D1: Growth Factor | E1: Neural Gain | F1: Reflex Gain | G1: Identity Confidence
A2: T000 | B2: 0 | C2: Embryogenesis | D2: 0.01 | E2: 0 | F2: 0 | G2: 0
A3: T500 | B3: 4 | C3: Organogenesis | D3: 0.1 | E3: 0.05 | F3: 0 | G3: 0
A4: T1000 | B4: 8 | C4: Body Plan | D4: 0.25 | E4: 0.1 | F4: 0.05 | G4: 0.1
A5: T1500 | B5: 12 | C5: Reflex Explosion | D5: 0.4 | E5: 0.25 | F5: 0.2 | G5: 0.25
A6: T2000 | B6: 20 | C6: Neural Maturation | D6: 0.6 | E6: 0.4 | F6: 0.4 | G6: 0.5
A7: T2500 | B7: 28 | C7: Pre‑Birth Integration | D7: 0.8 | E7: 0.6 | F7: 0.6 | G7: 0.75
A8: T3000 | B8: 36 | C8: Birth Preparation | D8: 0.95 | E8: 0.8 | F8: 0.8 | G8: 0.9
A9: T3200 | B9: 40 | C9: Birth Event | D9: 1 | E9: 1 | F9: 1 | G9: 1
A10: T3600 | B10: 45 | C10: Early Infant | D10: 1 | E10: 1 | F10: 1 | G10: 1
A11: T4000 | B11: 50 | C11: Early Infant | D11: 1 | E11: 1 | F11: 1 | G11: 1
A12: T4800 | B12: 60 | C12: Late Infant | D12: 1 | E12: 1 | F12: 1 | G12: 1
A13: T5600 | B13: 70 | C13: Late Infant | D13: 1 | E13: 1 | F13: 1 | G13: 1
... A17: T10000 | B17: 125 | C17: Early Childhood | D17: 1 | E17: 1 | F17: 1 | G17: 1

Sheet DNA Loop Engine
A1: 🧬 A7DO DNA LOOP ENGINE
A3: ⚙️ CONTROL PANEL | D3: 🫀 ORGAN ACTIVATION STATUS
A4: Current Tick: | B4: 4000 | D4: Organ/System | E4: Status | F4: DNA Code
A5: Current Week: | B5: =ROUND(B4/80,0) -> 50 | D5: Neural Plate | E5: =IF(B$5>=0,"✅ Active","⏳ Pending") -> ✅ Active | F5: NP_FORM
A6: Birth Tick: | B6: 3200 | D6: Heart | E6: =IF(B$5>=4,"✅ Active","⏳ Pending") -> ✅ Active | F6: HT_PART
A7: Nutrient Flow Rate: | B7: 1 | D7: Limbs | E7: =IF(B$5>=8,"✅ Active","⏳ Pending") -> ✅ Active | F7: LM_DIFF
A8: Simulation Status: | B8: =IF(B4>=B6,"🎉 BIRTH COMPLETE",IF(B4=0,"⏸️ NOT STARTED","🔄 GESTATING")) -> 🎉 BIRTH COMPLETE | D8: Reflex Arcs | E8: =IF(B$5>=12,"✅ Active","⏳ Pending") -> ✅ Active | F8: RF_ACT
D9: Cerebellum | E9: =IF(B$5>=20,"✅ Active","⏳ Pending") -> ✅ Active | F9: CB_GROW
A10: 📖 PHASE READER | D10: Myelination | E10: =IF(B$5>=28,"✅ Active","⏳ Pending") -> ✅ Active | F10: MYEL_ON
A11: Active Phase #: | B11: ="T"&TEXT(B4,"0000") -> T4000 | D11: Lungs | E11: =IF(B$5>=36,"✅ Active","⏳ Pending") -> ✅ Active | F11: LG_MAT
A12: DNA Phase Name: | B12: =IFERROR(_xlfn.XLOOKUP(B5,'Tick-Based DNA Loop'!B2:B17,'Tick-Based DNA Loop'!C2:C17,,"<=",-1),"Post-Birth Development") -> Post-Birth Development
A13: DNA Trigger Code: | B13: =IF(B5>=40,"POSTNATAL",IFERROR(VLOOKUP(B5,'Prenatal Phases'!B2:E8,4,TRUE),"N/A")) -> POSTNATAL | D13: 🔁 TICK ADVANCE LOGIC
A14: Biological Focus: | B14: =IF(B5>=40,"Post-Birth Growth & Learning",IFERROR(VLOOKUP(B5,'Prenatal Phases'!B2:C8,2,TRUE),"N/A")) -> Post-Birth Growth & Learning | D14: Next Tick ID: | E14: =IF(B4<B6, "T"&TEXT(B4+100,"0000"), "COMPLETE") -> COMPLETE
A15: Next Phase Condition: | B15: =IF(B5>=40,"Continuous Development",IFERROR(VLOOKUP(B5,'Prenatal Phases'!B2:F8,5,TRUE),"N/A")) -> Continuous Development | D15: Ticks to Birth: | E15: =MAX(0, B6-B4) -> 0
D16: Progress %: | E16: =B4/B6 -> 1.25
A17: ⚡ GROWTH ENGINE | D17: Time Remaining: | E17: =TEXT(INT(E15/100),"0")&" ticks (~"&ROUND(E15/80,1)&" weeks)" -> 0 ticks (~0 weeks)
A18: Growth Factor: | B18: =IF(B5>=40,1,IFERROR(_xlfn.XLOOKUP(B5,'Tick-Based DNA Loop'!B2:B17,'Tick-Based DNA Loop'!D2:D17,,"<=",-1),0)) -> 1 | D18: Phase Complete In: | E18: =IF(B5>=40,"N/A (Born)",MAX(0,40-B5)&" weeks") -> N/A (Born)
A19: Neural Gain: | B19: =IF(B5>=40,1,IFERROR(_xlfn.XLOOKUP(B5,'Tick-Based DNA Loop'!B2:B17,'Tick-Based DNA Loop'!E2:E17,,"<=",-1),0)) -> 1
A20: Reflex Gain: | B20: =IF(B5>=40,1,IFERROR(_xlfn.XLOOKUP(B5,'Tick-Based DNA Loop'!B2:B17,'Tick-Based DNA Loop'!F2:F17,,"<=",-1),0)) -> 1
A21: Identity Confidence: | B21: =IF(B5>=40,1,IFERROR(_xlfn.XLOOKUP(B5,'Tick-Based DNA Loop'!B2:B17,'Tick-Based DNA Loop'!G2:G17,,"<=",-1),0)) -> 1
A23: 🩸 UMBILICAL CORD DRIVER
A24: Nutrient Delivery: | B24: =IF(B4<B6, B7*B18, 0) -> 0
A25: DNA Push Rate: | B25: =IF(B4<B6, (B6-B4)/B6, 0) -> 0
A26: Oxygen Transfer: | B26: =IF(B4<B6, B7*0.21, 0.21) -> 0.21
A27: Cord Status: | B27: =IF(B4>=B6, "🔌 SEVERED", "🔗 CONNECTED") -> 🔌 SEVERED
A28: Effective Growth: | B28: =B18*B7 -> 1
A30: 🧭 POINT 0 — CENTRAL ORIGIN
A32: Parameter | B32: Value | C32: Unit | E32: 📐 COORDINATE SYSTEM
A33: X₀ (Horizontal) | B33: 0 | C33: m | E33: Axis | F33: Direction
A34: Y₀ (Vertical) | B34: 0 | C34: m | E34: +X | F34: Right
A35: Z₀ (Depth) | B35: 0 | C35: m | E35: -X | F35: Left
E36: +Y | F36: Up (Head)
A37: Reference Point: | B37: Pelvis Centre | E37: -Y | F37: Down (Feet)
A38: Body Height Factor: | B38: =IF(B5>=40,1,B18)*0.5 -> 0.5 | E38: +Z | F38: Forward
A39: Body Width Factor: | B39: =B38*0.4 -> 0.2 | E39: -Z | F39: Backward
A41: 🔗 SPATIAL COHERENCE
A42: All coordinates relative to Point 0
A45: 🧠 NEURAL CONTROL SUMMARY
A47: Control Hierarchy | B47: Region | C47: Status | D47: Pathways
A48: Cortical Motor | B48: Motor Cortex | C48: =COUNTIFS('Anatomy Growth Engine'!A177:A194,"Motor Cortex",'Anatomy Growth Engine'!K177:K194,"✅ Mature")&"/"&COUNTIF('Anatomy Growth Engine'!A177:A194,"Motor Cortex")&" mature" -> 4/4 mature | D48: 4
...

Sheet Respiratory Control
A1: Name | B1: Controlled Structure | C1: Neural Region | D1: Control Type | E1: Signal Pathway | F1: Feedback Source | G1: Activation Week | H1: Full Maturity Week | I1: Domain | J1: Current Week | K1: Growth Status | L1: Maturity %
A2: Lungs | B2: Organ | C2: Autonomic System | D2: Rhythmic | E2: Vagal Pathway | F2: Chemoreceptors | G2: 8 | H2: 28 | I2: Embodiment | J2: ='DNA Loop Engine'!$B$5 -> 50 | K2: =IF(J2<G2,"⏳ Dormant",IF(J2>=H2,"✅ Mature","🔄 Developing")) -> ✅ Mature | L2: =IF(J2<G2,0,IF(J2>=H2,100%,(J2-G2)/(H2-G2))) -> 1
A3: Trachea | B3: Organ | C3: Autonomic System | D3: Airflow Regulation | E3: Sympathetic Pathway | F3: Stretch Receptors | G3: 8 | H3: 28 | I3: Embodiment | J3: ='DNA Loop Engine'!$B$5 -> 50 | K3: =IF(J3<G3,"⏳ Dormant",IF(J3>=H3,"✅ Mature","🔄 Developing")) -> ✅ Mature | L3: =IF(J3<G3,0,IF(J3>=H3,100%,(J3-G3)/(H3-G3))) -> 1
A4: Bronchi | B4: Organ | C4: Autonomic System | D4: Air Distribution | E4: Vagal Pathway | F4: Pressure Sensors | G4: 8 | H4: 28 | I4: Embodiment | J4: ='DNA Loop Engine'!$B$5 -> 50 | K4: =IF(J4<G4,"⏳ Dormant",IF(J4>=H4,"✅ Mature","🔄 Developing")) -> ✅ Mature | L4: =IF(J4<G4,0,IF(J4>=H4,100%,(J4-G4)/(H4-G4))) -> 1
A5: Bronchioles | B5: Organ | C5: Autonomic System | D5: Micro-Airflow | E5: Local Autoregulation | F5: Oxygen Sensors | G5: 12 | H5: 28 | I5: Embodiment | J5: ='DNA Loop Engine'!$B$5 -> 50 | K5: =IF(J5<G5,"⏳ Dormant",IF(J5>=H5,"✅ Mature","🔄 Developing")) -> ✅ Mature | L5: =IF(J5<G5,0,IF(J5>=H5,100%,(J5-G5)/(H5-G5))) -> 1
A6: Alveoli | B6: Organ | C6: Autonomic System | D6: Oxygen Exchange | E6: Local Autoregulation | F6: O₂/CO₂ Sensors | G6: 12 | H6: 28 | I6: Embodiment | J6: ='DNA Loop Engine'!$B$5 -> 50 | K6: =IF(J6<G6,"⏳ Dormant",IF(J6>=H6,"✅ Mature","🔄 Developing")) -> ✅ Mature | L6: =IF(J6<G6,0,IF(J6>=H6,100%,(J6-G6)/(H6-G6))) -> 1
A7: Diaphragm | B7: Muscle | C7: Brainstem | D7: Rhythmic Motor | E7: Phrenic Nerve Pathway | F7: Stretch Receptors | G7: 8 | H7: 28 | I7: Motor Control | J7: ='DNA Loop Engine'!$B$5 -> 50 | K7: =IF(J7<G7,"⏳ Dormant",IF(J7>=H7,"✅ Mature","🔄 Developing")) -> ✅ Mature | L7: =IF(J7<G7,0,IF(J7>=H7,100%,(J7-G7)/(H7-G7))) -> 1
A8: Intercostal Muscles | B8: Muscle | C8: Brainstem | D8: Rhythmic Motor | E8: Spinal Respiratory Pathway | F8: Stretch Receptors | G8: 8 | H8: 28 | I8: Motor Control | J8: ='DNA Loop Engine'!$B$5 -> 50 | K8: =IF(J8<G8,"⏳ Dormant",IF(J8>=H8,"✅ Mature","🔄 Developing")) -> ✅ Mature | L8: =IF(J8<G8,0,IF(J8>=H8,100%,(J8-G8)/(H8-G8))) -> 1
A9: Nasal Cavity | B9: Organ | C9: Autonomic System | D9: Air Filtration | E9: Trigeminal Pathway | F9: Temperature Sensors | G9: 8 | H9: 28 | I9: Sensing | J9: ='DNA Loop Engine'!$B$5 -> 50 | K9: =IF(J9<G9,"⏳ Dormant",IF(J9>=H9,"✅ Mature","🔄 Developing")) -> ✅ Mature | L9: =IF(J9<G9,0,IF(J9>=H9,100%,(J9-G9)/(H9-G9))) -> 1
A10: Pharynx | B10: Organ | C10: Autonomic System | D10: Air Passage | E10: Glossopharyngeal Pathway | F10: Pressure Sensors | G10: 8 | H10: 28 | I10: Sensing | J10: ='DNA Loop Engine'!$B$5 -> 50 | K10: =IF(J10<G10,"⏳ Dormant",IF(J10>=H10,"✅ Mature","🔄 Developing")) -> ✅ Mature | L10: =IF(J10<G10,0,IF(J10>=H10,100%,(J10-G10)/(H10-G10))) -> 1
A11: Larynx | B11: Organ | C11: Autonomic System | D11: Airflow Modulation | E11: Vagal Pathway | F11: Sound/Vibration Sensors | G11: 8 | H11: 28 | I11: Sensing | J11: ='DNA Loop Engine'!$B$5 -> 50 | K11: =IF(J11<G11,"⏳ Dormant",IF(J11>=H11,"✅ Mature","🔄 Developing")) -> ✅ Mature | L11: =IF(J11<G11,0,IF(J11>=H11,100%,(J11-G11)/(H11-G11))) -> 1

Sheet Circulatory System
A1: Name | B1: Controlled Structure | C1: Neural Region | D1: Control Type | E1: Signal Pathway | F1: Feedback Source | G1: Activation Week | H1: Full Maturity Week | I1: Domain | J1: Current Week | K1: Growth Status | L1: Maturity % | M1: Local X | N1: Local Y | O1: Local Z | P1: Connection To | Q1: Flow Direction | R1: Flow Rate Factor
A2: Heart | B2: Organ | C2: Autonomic System | D2: Homeostatic | E2: Vagal Pathway | F2: Baroreceptors | G2: 8 | H2: 28 | I2: Embodiment | J2: ='DNA Loop Engine'!$B$5 -> 50 | K2: =IF(J2<G2,"⏳ Pending",IF(J2>=H2,"✅ Mature","🔄 Developing")) -> ✅ Mature | L2: =IF(J2<G2,0%,IF(J2>=H2,100%,(J2-G2)/(H2-G2))) -> 1 | M2: 0 | N2: 0.35 | O2: 0.05 | P2: Sternum | Q2: Central Pump | R2: 1
A3: Aorta | B3: Vessel | C3: Autonomic System | D3: Pressure Regulation | E3: Sympathetic Pathway | F3: Stretch Receptors | G3: 8 | H3: 28 | I3: Embodiment | J3: ='DNA Loop Engine'!$B$5 -> 50 | K3: =IF(J3<G3,"⏳ Pending",IF(J3>=H3,"✅ Mature","🔄 Developing")) -> ✅ Mature | L3: =IF(J3<G3,0%,IF(J3>=H3,100%,(J3-G3)/(H3-G3))) -> 1 | M3: 0 | N3: 0.4 | O3: 0.03 | P3: Heart | Q3: Ascending | R3: 0.95
A4: Pulmonary Artery | B4: Vessel | C4: Autonomic System | D4: Oxygen Exchange | E4: Vagal Pathway | F4: Chemoreceptors | G4: 8 | H4: 28 | I4: Embodiment | J4: ='DNA Loop Engine'!$B$5 -> 50 | K4: =IF(J4<G4,"⏳ Pending",IF(J4>=H4,"✅ Mature","🔄 Developing")) -> ✅ Mature | L4: =IF(J4<G4,0%,IF(J4>=H4,100%,(J4-G4)/(H4-G4))) -> 1 | M4: 0 | N4: 0.38 | O4: -0.02 | P4: Heart | Q4: To Lungs | R4: 0.9
A5: Pulmonary Veins | B5: Vessel | C5: Autonomic System | D5: Oxygen Return | E5: Vagal Pathway | F5: Chemoreceptors | G5: 8 | H5: 28 | I5: Embodiment | J5: ='DNA Loop Engine'!$B$5 -> 50 | K5: =IF(J5<G5,"⏳ Pending",IF(J5>=H5,"✅ Mature","🔄 Developing")) -> ✅ Mature | L5: =IF(J5<G5,0%,IF(J5>=H5,100%,(J5-G5)/(H5-G5))) -> 1 | M5: 0 | N5: 0.36 | O5: -0.02 | P5: Lungs | Q5: From Lungs | R5: 0.9
A6: Vena Cava | B6: Vessel | C6: Autonomic System | D6: Venous Return | E6: Sympathetic Pathway | F6: Pressure Sensors | G6: 8 | H6: 28 | I6: Embodiment | J6: ='DNA Loop Engine'!$B$5 -> 50 | K6: =IF(J6<G6,"⏳ Pending",IF(J6>=H6,"✅ Mature","🔄 Developing")) -> ✅ Mature | L6: =IF(J6<G6,0%,IF(J6>=H6,100%,(J6-G6)/(H6-G6))) -> 1 | M6: 0 | N6: 0.3 | O6: 0 | P6: Heart | Q6: To Heart | R6: 0.85
A7: Coronary Arteries | B7: Vessel | C7: Autonomic System | D7: Cardiac Perfusion | E7: Sympathetic Pathway | F7: Baroreceptors | G7: 8 | H7: 28 | I7: Embodiment | J7: ='DNA Loop Engine'!$B$5 -> 50 | K7: =IF(J7<G7,"⏳ Pending",IF(J7>=H7,"✅ Mature","🔄 Developing")) -> ✅ Mature | L7: =IF(J7<G7,0%,IF(J7>=H7,100%,(J7-G7)/(H7-G7))) -> 1 | M7: 0.02 | N7: 0.36 | O7: 0.04 | P7: Aorta | Q7: Cardiac Supply | R7: 0.8
A8: Capillary Networks | B8: Vessel | C8: Autonomic System | D8: Microcirculation | E8: Local Autoregulation | F8: Oxygen Sensors | G8: 12 | H8: 28 | I8: Embodiment | J8: ='DNA Loop Engine'!$B$5 -> 50 | K8: =IF(J8<G8,"⏳ Pending",IF(J8>=H8,"✅ Mature","🔄 Developing")) -> ✅ Mature | L8: =IF(J8<G8,0%,IF(J8>=H8,100%,(J8-G8)/(H8-G8))) -> 1 | M8: 0 | N8: 0 | O8: 0 | P8: Arterioles | Q8: Bidirectional | R8: 0.7
A9: Blood | B9: Fluid | C9: Autonomic System | D9: Transport Medium | E9: Endocrine Feedback | F9: Hemoglobin Sensors | G9: 12 | H9: 28 | I9: Embodiment | J9: ='DNA Loop Engine'!$B$5 -> 50 | K9: =IF(J9<G9,"⏳ Pending",IF(J9>=H9,"✅ Mature","🔄 Developing")) -> ✅ Mature | L9: =IF(J9<G9,0%,IF(J9>=H9,100%,(J9-G9)/(H9-G9))) -> 1 | M9: 0 | N9: 0 | O9: 0 | P9: All Vessels | Q9: Circulating | R9: 1
A10: Superior Vena Cava | B10: Vessel | C10: Autonomic System | D10: Upper Body Return | E10: Sympathetic Pathway | F10: Pressure Sensors | G10: 8 | H10: 28 | I10: Embodiment | J10: ='DNA Loop Engine'!$B$5 -> 50 | K10: =IF(J10<G10,"⏳ Pending",IF(J10>=H10,"✅ Mature","🔄 Developing")) -> ✅ Mature | L10: =IF(J10<G10,0%,IF(J10>=H10,100%,(J10-G10)/(H10-G10))) -> 1 | M10: 0 | N10: 0.45 | O10: 0 | P10: Heart | Q10: Upper Return | R10: 0.85
A11: Inferior Vena Cava | B11: Vessel | C11: Autonomic System | D11: Lower Body Return | E11: Sympathetic Pathway | F11: Pressure Sensors | G11: 8 | H11: 28 | I11: Embodiment | J11: ='DNA Loop Engine'!$B$5 -> 50 | K11: =IF(J11<G11,"⏳ Pending",IF(J11>=H11,"✅ Mature","🔄 Developing")) -> ✅ Mature | L11: =IF(J11<G11,0%,IF(J11>=H11,100%,(J11-G11)/(H11-G11))) -> 1 | M11: 0 | N11: 0.2 | O11: 0 | P11: Heart | Q11: Lower Return | R11: 0.85
A12: Carotid Arteries | B12: Vessel | C12: Autonomic System | D12: Cerebral Perfusion | E12: Sympathetic Pathway | F12: Baroreceptors | G12: 8 | H12: 28 | I12: Embodiment | J12: ='DNA Loop Engine'!$B$5 -> 50 | K12: =IF(J12<G12,"⏳ Pending",IF(J12>=H12,"✅ Mature","🔄 Developing")) -> ✅ Mature | L12: =IF(J12<G12,0%,IF(J12>=H12,100%,(J12-G12)/(H12-G12))) -> 1 | M12: 0.05 | N12: 0.6 | O12: 0.02 | P12: Aorta | Q12: To Brain | R12: 0.9
A13: Jugular Veins | B13: Vessel | C13: Autonomic System | D13: Cerebral Drainage | E13: Sympathetic Pathway | F13: Pressure Sensors | G13: 8 | H13: 28 | I13: Embodiment | J13: ='DNA Loop Engine'!$B$5 -> 50 | K13: =IF(J13<G13,"⏳ Pending",IF(J13>=H13,"✅ Mature","🔄 Developing")) -> ✅ Mature | L13: =IF(J13<G13,0%,IF(J13>=H13,100%,(J13-G13)/(H13-G13))) -> 1 | M13: 0.06 | N13: 0.55 | O13: 0 | P13: Brain | Q13: From Brain | R13: 0.85
... A19: Foramen Ovale | B19: Fetal Shunt | C19: Autonomic System | D19: Atrial Shunt | E19: Local Autoregulation | F19: Pressure Sensors | G19: 6 | H19: 40 | I19: Embodiment | J19: ='DNA Loop Engine'!$B$5 -> 50 | K19: =IF(J19<G19,"⏳ Pending",IF(J19>=H19,"✅ Mature","🔄 Developing")) -> ✅ Mature | L19: =IF(J19<G19,0%,IF(J19>=H19,100%,(J19-G19)/(H19-G19))) -> 1 | M19: 0 | N19: 0.35 | O19: 0.02 | P19: Atria | Q19: Atrial Bypass | R19: 0.9
A22: 🩸 CIRCULATORY SYSTEM SUMMARY
A24: Parameter | B24: Value | C24: Unit | E24: 🔗 CROSS-SYSTEM LINKS
A25: Total Components: | B25: =COUNTA(CirculatorySystem[Name]) -> 18 | E25: Linked Sheet | F25: Connection
A26: Vessels: | B26: =COUNTIF(CirculatorySystem[Controlled Structure],"Vessel") -> 14 | E26: DNA Loop Engine | F26: Current Week (B5)
A27: Organs: | B27: =COUNTIF(CirculatorySystem[Controlled Structure],"Organ") -> 1 | E27: Respiratory Control | F27: O₂ Exchange
A28: Fetal Shunts: | B28: =COUNTIF(CirculatorySystem[Controlled Structure],"Fetal Shunt") -> 2 | E28: Anatomy Growth Engine | F28: Heart Coordinates
A29: Fluids: | B29: =COUNTIF(CirculatorySystem[Controlled Structure],"Fluid") -> 1 | E29: Neural Control | F29: Autonomic Pathways
A31: ⏳ Pending: | B31: =COUNTIF(CirculatorySystem[Growth Status],"⏳ Pending") -> 0
A32: 🔄 Developing: | B32: =COUNTIF(CirculatorySystem[Growth Status],"🔄 Developing") -> 0
A33: ✅ Mature: | B33: =COUNTIF(CirculatorySystem[Growth Status],"✅ Mature") -> 18
A35: Average Maturity: | B35: =AVERAGE(CirculatorySystem[Maturity %]) -> 1 | C35: %
A37: 🫀 CARDIAC METRICS (from DNA Loop Engine)
A39: Heart Rate: | B39: ='DNA Loop Engine'!B59 -> 137.96154 | C39: BPM | E39: Status: | F39: ='DNA Loop Engine'!B67 -> ✅ MATURE
A40: Cardiac Output: | B40: ='DNA Loop Engine'!B60 -> 0.276 | C40: L/min
A41: Blood Flow: | B41: ='DNA Loop Engine'!B61 -> 0.552 | C41: L/min
A42: Blood Volume: | B42: ='DNA Loop Engine'!E65 -> 300 mL
A44: 🔗 RESPIRATORY SYNC
A46: O₂ Delivery Rate: | B46: ='DNA Loop Engine'!B83 -> 0.39192 | C46: L O₂/min
A47: CO₂ Removal Rate: | B47: ='DNA Loop Engine'!B84 -> 0.04968 | C47: L CO₂/min
A48: System Sync: | B48: ='DNA Loop Engine'!E83 -> 🟢 SYNCHRONIZED
A50: 🧬 FETAL CIRCULATION STATUS
A52: Umbilical Flow: | B52: =IF('DNA Loop Engine'!B5<40,"🔗 ACTIVE","❌ SEVERED") -> ❌ SEVERED
A53: Ductus Arteriosus: | B53: =IF('DNA Loop Engine'!B5<40,"🔓 OPEN","🔒 CLOSING") -> 🔒 CLOSING
A54: Foramen Ovale: | B54: =IF('DNA Loop Engine'!B5<40,"🔓 OPEN","🔒 CLOSING") -> 🔒 CLOSING

Sheet Digestive Control
A1: Name | B1: Controlled Structure | C1: Neural Region | D1: Control Type | E1: Signal Pathway | F1: Feedback Source | G1: Activation Week | H1: Full Maturity Week | I1: Domain | J1: Current Week | K1: Growth Status | L1: Maturity % | M1: Local X | N1: Local Y | O1: Local Z | P1: Connection To | Q1: Flow Direction | R1: Flow Rate Factor
A2: Mouth | B2: Organ | C2: Brainstem | D2: Autonomic | E2: Trigeminal Pathway | F2: Taste Receptors | G2: 8 | H2: 28 | I2: Sensing | J2: ='DNA Loop Engine'!$B$5 -> 50 | K2: =IF(J2<G2,"⏳ Pending",IF(J2>=H2,"✅ Mature","🔄 Developing")) -> ✅ Mature | L2: =IF(J2<G2,0,IF(J2>=H2,1,(J2-G2)/(H2-G2))) -> 1 | M2: 0 | N2: 0.7 | O2: 0.12 | P2: Skull | Q2: Intake | R2: 0.9
A3: Pharynx | B3: Organ | C3: Brainstem | D3: Autonomic | E3: Glossopharyngeal Pathway | F3: Pressure Sensors | G3: 8 | H3: 28 | I3: Sensing | J3: ='DNA Loop Engine'!$B$5 -> 50 | K3: =IF(J3<G3,"⏳ Pending",IF(J3>=H3,"✅ Mature","🔄 Developing")) -> ✅ Mature | L3: =IF(J3<G3,0,IF(J3>=H3,1,(J3-G3)/(H3-G3))) -> 1 | M3: 0 | N3: 0.65 | O3: 0.08 | P3: Mouth | Q3: Passage | R3: 0.85
A4: Esophagus | B4: Organ | C4: Autonomic System | D4: Peristaltic | E4: Vagal Pathway | F4: Stretch Receptors | G4: 8 | H4: 28 | I4: Embodiment | J4: ='DNA Loop Engine'!$B$5 -> 50 | K4: =IF(J4<G4,"⏳ Pending",IF(J4>=H4,"✅ Mature","🔄 Developing")) -> ✅ Mature | L4: =IF(J4<G4,0,IF(J4>=H4,1,(J4-G4)/(H4-G4))) -> 1 | M4: 0 | N4: 0.5 | O4: 0.02 | P4: Pharynx | Q4: Descending | R4: 0.8
A5: Stomach | B5: Organ | C5: Autonomic System | D5: Churning | E5: Vagal Pathway | F5: Chemical Sensors | G5: 8 | H5: 28 | I5: Embodiment | J5: ='DNA Loop Engine'!$B$5 -> 50 | K5: =IF(J5<G5,"⏳ Pending",IF(J5>=H5,"✅ Mature","🔄 Developing")) -> ✅ Mature | L5: =IF(J5<G5,0,IF(J5>=H5,1,(J5-G5)/(H5-G5))) -> 1 | M5: 0.05 | N5: 0.3 | O5: 0.05 | P5: Esophagus | Q5: Processing | R5: 0.85
A6: Small Intestine | B6: Organ | C6: Autonomic System | D6: Peristaltic | E6: Vagal Pathway | F6: Nutrient Sensors | G6: 12 | H6: 28 | I6: Embodiment | J6: ='DNA Loop Engine'!$B$5 -> 50 | K6: =IF(J6<G6,"⏳ Pending",IF(J6>=H6,"✅ Mature","🔄 Developing")) -> ✅ Mature | L6: =IF(J6<G6,0,IF(J6>=H6,1,(J6-G6)/(H6-G6))) -> 1 | M6: 0 | N6: 0.15 | O6: 0.05 | P6: Stomach | Q6: Absorption | R6: 0.9
A7: Large Intestine | B7: Organ | C7: Autonomic System | D7: Absorptive | E7: Local Autoregulation | F7: Pressure Sensors | G7: 12 | H7: 28 | I7: Embodiment | J7: ='DNA Loop Engine'!$B$5 -> 50 | K7: =IF(J7<G7,"⏳ Pending",IF(J7>=H7,"✅ Mature","🔄 Developing")) -> ✅ Mature | L7: =IF(J7<G7,0,IF(J7>=H7,1,(J7-G7)/(H7-G7))) -> 1 | M7: 0.08 | N7: 0.1 | O7: 0 | P7: Small Intestine | Q7: Processing | R7: 0.75
A8: Liver | B8: Organ | C8: Autonomic System | D8: Metabolic Regulation | E8: Sympathetic Pathway | F8: Glucose Sensors | G8: 12 | H8: 28 | I8: Embodiment | J8: ='DNA Loop Engine'!$B$5 -> 50 | K8: =IF(J8<G8,"⏳ Pending",IF(J8>=H8,"✅ Mature","🔄 Developing")) -> ✅ Mature | L8: =IF(J8<G8,0,IF(J8>=H8,1,(J8-G8)/(H8-G8))) -> 1 | M8: 0.1 | N8: 0.28 | O8: 0.03 | P8: Hepatic Portal Vein | Q8: Filtration | R8: 0.95
A9: Gallbladder | B9: Organ | C9: Autonomic System | D9: Bile Release | E9: Vagal Pathway | F9: Chemical Sensors | G9: 12 | H9: 28 | I9: Embodiment | J9: ='DNA Loop Engine'!$B$5 -> 50 | K9: =IF(J9<G9,"⏳ Pending",IF(J9>=H9,"✅ Mature","🔄 Developing")) -> ✅ Mature | L9: =IF(J9<G9,0,IF(J9>=H9,1,(J9-G9)/(H9-G9))) -> 1 | M9: 0.08 | N9: 0.26 | O9: 0.04 | P9: Liver | Q9: Secretion | R9: 0.7
A10: Pancreas | B10: Organ | C10: Autonomic System | D10: Enzyme Secretion | E10: Sympathetic Pathway | F10: Glucose Sensors | G10: 12 | H10: 28 | I10: Embodiment | J10: ='DNA Loop Engine'!$B$5 -> 50 | K10: =IF(J10<G10,"⏳ Pending",IF(J10>=H10,"✅ Mature","🔄 Developing")) -> ✅ Mature | L10: =IF(J10<G10,0,IF(J10>=H10,1,(J10-G10)/(H10-G10))) -> 1 | M10: -0.05 | N10: 0.25 | O10: 0.02 | P10: Stomach | Q10: Secretion | R10: 0.85
A11: Rectum | B11: Organ | C11: Autonomic System | D11: Expulsion Control | E11: Spinal Reflex Arc | F11: Pressure Sensors | G11: 12 | H11: 28 | I11: Embodiment | J11: ='DNA Loop Engine'!$B$5 -> 50 | K11: =IF(J11<G11,"⏳ Pending",IF(J11>=H11,"✅ Mature","🔄 Developing")) -> ✅ Mature | L11: =IF(J11<G11,0,IF(J11>=H11,1,(J11-G11)/(H11-G11))) -> 1 | M11: 0 | N11: -0.15 | O11: -0.05 | P11: Large Intestine | Q11: Output | R11: 0.6
A14: 🍽️ DIGESTIVE SYSTEM SUMMARY
A16: Parameter | B16: Value | C16: Unit | E16: 🔗 CROSS-SYSTEM LINKS
A17: Total Components: | B17: =COUNTA(DigestiveControl[Name]) -> 10 | E17: Linked Sheet | F17: Connection
A18: Organs: | B18: =COUNTIF(DigestiveControl[Controlled Structure],"Organ") -> 10 | E18: DNA Loop Engine | F18: Current Week (B5)
E19: Circulatory System | F19: Nutrient Transport
A20: ⏳ Pending: | B20: =COUNTIF(DigestiveControl[Growth Status],"⏳ Pending") -> 0 | E20: Respiratory Control | F20: O₂ for Metabolism
A21: 🔄 Developing: | B21: =COUNTIF(DigestiveControl[Growth Status],"🔄 Developing") -> 0 | E21: Anatomy Growth Engine | F21: Organ Coordinates
A22: ✅ Mature: | B22: =COUNTIF(DigestiveControl[Growth Status],"✅ Mature") -> 10 | E22: Umbilical System | F22: Prenatal Nutrients
A24: Average Maturity: | B24: =AVERAGE(DigestiveControl[Maturity %]) -> 1 | C24: %
A27: 🥗 DIGESTIVE METRICS DASHBOARD
A29: Parameter | B29: Value | C29: Unit | E29: Status | F29: Visual
A30: Peristalsis Rate: | B30: =20+('DNA Loop Engine'!B18*30) -> 50 | C30: cycles/min | E30: 🔄 Peristaltic Motion: | F30: 🌊 🌊 🌊 🌊 🌊
A31: Nutrient Demand: | B31: ='DNA Loop Engine'!B18*0.8 -> 0.8 | C31: (0-1) | E31: Gut Activity: | F31: =IF(B31>0.5,"Active churning","Minimal activity") -> Active churning
A32: Absorption Efficiency: | B32: =AVERAGE(DigestiveControl[Maturity %])*0.95 -> 0.95 | C32: %
A33: Enzyme Secretion: | B33: =AVERAGE(DigestiveControl[Maturity %])*0.9 -> 0.9 | C33: (0-1) | E33: 🧬 Enzyme Status: | F33: =IF(B33>0.7,"Full secretion","Developing") -> Full secretion
A34: Bile Flow: | B34: =INDEX(DigestiveControl[Maturity %],MATCH("Gallbladder",DigestiveControl[Name],0))*0.8 -> 0.8 | C34: (0-1)
A35: Glucose Processing: | B35: =INDEX(DigestiveControl[Maturity %],MATCH("Liver",DigestiveControl[Name],0)) -> 1 | C35: (0-1) | E35: 🍬 Glucose Status: | F35: =IF(B35>0.7,"Metabolizing","Developing") -> Metabolizing
A36: Waste Output: | B36: =INDEX(DigestiveControl[Maturity %],MATCH("Rectum",DigestiveControl[Name],0))*0.5 -> 0.5 | C36: (0-1)
A38: Digestive Maturity: | B38: =AVERAGE(DigestiveControl[Maturity %]) -> 1 | C38: %
A39: Digestive Status: | B39: =IF(B38<0.5,"⏳ IMMATURE",IF(B38<1,"🔄 DEVELOPING","✅ MATURE")) -> ✅ MATURE
A42: 🔗 NUTRIENT-CIRCULATORY INTEGRATION
A44: Metric | B44: Value | C44: Unit | E44: Sync Status
A45: Nutrient Delivery Rate: | B45: ='DNA Loop Engine'!B24 -> 0 | C45: (0-1) | E45: =IF(B45>0.5,"🟢 OPTIMAL","🟡 DEVELOPING") -> 🟡 DEVELOPING
A46: Hepatic Portal Flow: | B46: =INDEX('Circulatory System'!R:R,MATCH("Hepatic Portal Vein",'Circulatory System'!A:A,0))*B45 -> 0 | C46: (0-1)
A47: Glucose to Blood: | B47: =B35*'DNA Loop Engine'!B18 -> 1 | C47: (0-1) | E47: =IF(B47>0.3,"🟢 ACTIVE","🟡 MINIMAL") -> 🟢 ACTIVE
A48: Metabolic Sync: | B48: =IF(AND(B45>0.5,B46>0.5),"🟢 SYNCHRONIZED","🟡 DEVELOPING") -> 🟡 DEVELOPING
A51: 🫀 UMBILICAL NUTRIENT PATHWAY
A53: Pathway | B53: Status | C53: Flow Rate | E53: Notes
A54: Umbilical Vein → Liver: | B54: =IF('DNA Loop Engine'!B5<40,"🔗 ACTIVE","🔒 CLOSED") -> 🔒 CLOSED | C54: ='DNA Loop Engine'!B24*0.9 -> 0 | E54: Nutrients from placenta
...

Sheet Sensory Integration
A1: Name | B1: Controlled Structure | C1: Neural Region | D1: Control Type | E1: Signal Pathway | F1: Feedback Source | G1: Activation Week | H1: Full Maturity Week | I1: Domain | J1: Current Week | K1: Growth Status | L1: Maturity % | M1: Local X | N1: Local Y | O1: Local Z | P1: Connection To | Q1: Receptor Gain | R1: Signal Strength | S1: Sensory Modality
A2: Eyes | B2: Organ | C2: Cerebrum | D2: Sensory | E2: Optic Pathway | F2: Retina Photoreceptors | G2: 20 | H2: 36 | I2: Sensing | J2: ='DNA Loop Engine'!$B$5 -> 50 | K2: =IF(J2<G2,"⏳ Dormant",IF(J2>=H2,"✅ Mature","🔄 Developing")) -> ✅ Mature | L2: =IF(J2<G2,0%,IF(J2>=H2,100%,(J2-G2)/(H2-G2))) -> 1 | M2: 0.03 | N2: 0.76 | O2: 0.1 | P2: Skull | Q2: 0.85 | R2: =Q2*(1+'DNA Loop Engine'!$B$18) -> 1.7 | S2: Vision
A3: Retina | B3: Organ | C3: Cerebrum | D3: Sensory | E3: Optic Pathway | F3: Light Receptors | G3: 20 | H3: 36 | I3: Sensing | J3: ='DNA Loop Engine'!$B$5 -> 50 | K3: =IF(J3<G3,"⏳ Dormant",IF(J3>=H3,"✅ Mature","🔄 Developing")) -> ✅ Mature | L3: =IF(J3<G3,0%,IF(J3>=H3,100%,(J3-G3)/(H3-G3))) -> 1 | M3: 0.03 | N3: 0.76 | O3: 0.11 | P3: Eyes | Q3: 0.9 | R3: =Q3*(1+'DNA Loop Engine'!$B$18) -> 1.8 | S3: Vision
A4: Optic Nerve | B4: Nerve | C4: Cerebrum | D4: Sensory | E4: Optic Pathway | F4: Visual Cortex | G4: 20 | H4: 36 | I4: Sensing | J4: ='DNA Loop Engine'!$B$5 -> 50 | K4: =IF(J4<G4,"⏳ Dormant",IF(J4>=H4,"✅ Mature","🔄 Developing")) -> ✅ Mature | L4: =IF(J4<G4,0%,IF(J4>=H4,100%,(J4-G4)/(H4-G4))) -> 1 | M4: 0.02 | N4: 0.78 | O4: 0.05 | P4: Retina | Q4: 0.8 | R4: =Q4*(1+'DNA Loop Engine'!$B$18) -> 1.6 | S4: Vision
A5: Ears | B5: Organ | C5: Brainstem | D5: Sensory | E5: Auditory Pathway | F5: Cochlear Hair Cells | G5: 20 | H5: 36 | I5: Sensing | J5: ='DNA Loop Engine'!$B$5 -> 50 | K5: =IF(J5<G5,"⏳ Dormant",IF(J5>=H5,"✅ Mature","🔄 Developing")) -> ✅ Mature | L5: =IF(J5<G5,0%,IF(J5>=H5,100%,(J5-G5)/(H5-G5))) -> 1 | M5: 0.12 | N5: 0.78 | O5: -0.02 | P5: Skull | Q5: 0.85 | R5: =Q5*(1+'DNA Loop Engine'!$B$18) -> 1.7 | S5: Auditory
A6: Cochlea | B6: Organ | C6: Brainstem | D6: Sensory | E6: Auditory Pathway | F6: Sound Receptors | G6: 20 | H6: 36 | I6: Sensing | J6: ='DNA Loop Engine'!$B$5 -> 50 | K6: =IF(J6<G6,"⏳ Dormant",IF(J6>=H6,"✅ Mature","🔄 Developing")) -> ✅ Mature | L6: =IF(J6<G6,0%,IF(J6>=H6,100%,(J6-G6)/(H6-G6))) -> 1 | M6: 0.13 | N6: 0.78 | O6: -0.03 | P6: Ears | Q6: 0.9 | R6: =Q6*(1+'DNA Loop Engine'!$B$18) -> 1.8 | S6: Auditory
A7: Auditory Nerve | B7: Nerve | C7: Cerebrum | D7: Sensory | E7: Auditory Pathway | F7: Temporal Cortex | G7: 20 | H7: 36 | I7: Sensing | J7: ='DNA Loop Engine'!$B$5 -> 50 | K7: =IF(J7<G7,"⏳ Dormant",IF(J7>=H7,"✅ Mature","🔄 Developing")) -> ✅ Mature | L7: =IF(J7<G7,0%,IF(J7>=H7,100%,(J7-G7)/(H7-G7))) -> 1 | M7: 0.1 | N7: 0.8 | O7: -0.02 | P7: Cochlea | Q7: 0.8 | R7: =Q7*(1+'DNA Loop Engine'!$B$18) -> 1.6 | S7: Auditory
A8: Skin | B8: Organ | C8: Spinal Cord | D8: Sensory | E8: Somatosensory Pathway | F8: Mechanoreceptors | G8: 12 | H8: 36 | I8: Sensing | J8: ='DNA Loop Engine'!$B$5 -> 50 | K8: =IF(J8<G8,"⏳ Dormant",IF(J8>=H8,"✅ Mature","🔄 Developing")) -> ✅ Mature | L8: =IF(J8<G8,0%,IF(J8>=H8,100%,(J8-G8)/(H8-G8))) -> 1 | M8: 0 | N8: 0 | O8: 0 | P8: Body Surface | Q8: 0.75 | R8: =Q8*(1+'DNA Loop Engine'!$B$18) -> 1.5 | S8: Touch
A9: Mechanoreceptors | B9: Cell | C9: Spinal Cord | D9: Sensory | E9: Somatosensory Pathway | F9: Touch Pressure Sensors | G9: 12 | H9: 36 | I9: Sensing | J9: ='DNA Loop Engine'!$B$5 -> 50 | K9: =IF(J9<G9,"⏳ Dormant",IF(J9>=H9,"✅ Mature","🔄 Developing")) -> ✅ Mature | L9: =IF(J9<G9,0%,IF(J9>=H9,100%,(J9-G9)/(H9-G9))) -> 1 | M9: 0 | N9: 0 | O9: 0.01 | P9: Skin | Q9: 0.85 | R9: =Q9*(1+'DNA Loop Engine'!$B$18) -> 1.7 | S9: Touch
A10: Thermoreceptors | B10: Cell | C10: Spinal Cord | D10: Sensory | E10: Somatosensory Pathway | F10: Temperature Sensors | G10: 12 | H10: 36 | I10: Sensing | J10: ='DNA Loop Engine'!$B$5 -> 50 | K10: =IF(J10<G10,"⏳ Dormant",IF(J10>=H10,"✅ Mature","🔄 Developing")) -> ✅ Mature | L10: =IF(J10<G10,0%,IF(J10>=H10,100%,(J10-G10)/(H10-G10))) -> 1 | M10: 0 | N10: 0 | O10: 0.01 | P10: Skin | Q10: 0.8 | R10: =Q10*(1+'DNA Loop Engine'!$B$18) -> 1.6 | S10: Touch
A11: Nociceptors | B11: Cell | C11: Spinal Cord | D11: Sensory | E11: Somatosensory Pathway | F11: Pain Sensors | G11: 12 | H11: 36 | I11: Sensing | J11: ='DNA Loop Engine'!$B$5 -> 50 | K11: =IF(J11<G11,"⏳ Dormant",IF(J11>=H11,"✅ Mature","🔄 Developing")) -> ✅ Mature | L11: =IF(J11<G11,0%,IF(J11>=H11,100%,(J11-G11)/(H11-G11))) -> 1 | M11: 0 | N11: 0 | O11: 0.01 | P11: Skin | Q11: 0.7 | R11: =Q11*(1+'DNA Loop Engine'!$B$18) -> 1.4 | S11: Touch
A12: Tongue | B12: Organ | C12: Brainstem | D12: Sensory | E12: Gustatory Pathway | F12: Taste Buds | G12: 12 | H12: 36 | I12: Sensing | J12: ='DNA Loop Engine'!$B$5 -> 50 | K12: =IF(J12<G12,"⏳ Dormant",IF(J12>=H12,"✅ Mature","🔄 Developing")) -> ✅ Mature | L12: =IF(J12<G12,0%,IF(J12>=H12,100%,(J12-G12)/(H12-G12))) -> 1 | M12: 0 | N12: 0.68 | O12: 0.08 | P12: Mouth | Q12: 0.8 | R12: =Q12*(1+'DNA Loop Engine'!$B$18) -> 1.6 | S12: Taste
A13: Taste Buds | B13: Cell | C13: Brainstem | D13: Sensory | E13: Gustatory Pathway | F13: Chemical Sensors | G13: 12 | H13: 36 | I13: Sensing | J13: ='DNA Loop Engine'!$B$5 -> 50 | K13: =IF(J13<G13,"⏳ Dormant",IF(J13>=H13,"✅ Mature","🔄 Developing")) -> ✅ Mature | L13: =IF(J13<G13,0%,IF(J13>=H13,100%,(J13-G13)/(H13-G13))) -> 1 | M13: 0 | N13: 0.68 | O13: 0.09 | P13: Tongue | Q13: 0.85 | R13: =Q13*(1+'DNA Loop Engine'!$B$18) -> 1.7 | S13: Taste
... A16: Vestibular System | B16: Organ | C16: Brainstem | D16: Sensory | E16: Vestibular Pathway | F16: Balance Receptors | G16: 12 | H16: 36 | I16: Sensing | J16: ='DNA Loop Engine'!$B$5 -> 50 | K16: =IF(J16<G16,"⏳ Dormant",IF(J16>=H16,"✅ Mature","🔄 Developing")) -> ✅ Mature | L16: =IF(J16<G16,0%,IF(J16>=H16,100%,(J16-G16)/(H16-G16))) -> 1 | M16: 0.12 | N16: 0.79 | O16: -0.04 | P16: Ears | Q16: 0.85 | R16: =Q16*(1+'DNA Loop Engine'!$B$18) -> 1.7 | S16: Balance
A19: 👁️ SENSORY SYSTEM SUMMARY
A21: Sensory Modality | B21: Components | C21: Neural Region | D21: Avg Maturity | E21: Avg Signal | F21: Status
A22: Vision | B22: =COUNTIF(S2:S16,"Vision") -> 3 | C22: Cerebrum | D22: =AVERAGEIF(S2:S16,"Vision",L2:L16) -> 1 | E22: =AVERAGEIF(S2:S16,"Vision",R2:R16) -> 1.7 | F22: =IF(D22<0.3,"⏳ Dormant",IF(D22<1,"🔄 Developing","✅ Mature")) -> ✅ Mature
A23: Auditory | B23: =COUNTIF(S2:S16,"Auditory") -> 3 | C23: Brainstem/Cerebrum | D23: =AVERAGEIF(S2:S16,"Auditory",L2:L16) -> 1 | E23: =AVERAGEIF(S2:S16,"Auditory",R2:R16) -> 1.7 | F23: =IF(D23<0.3,"⏳ Dormant",IF(D23<1,"🔄 Developing","✅ Mature")) -> ✅ Mature
A24: Touch | B24: =COUNTIF(S2:S16,"Touch") -> 4 | C24: Spinal Cord | D24: =AVERAGEIF(S2:S16,"Touch",L2:L16) -> 1 | E24: =AVERAGEIF(S2:S16,"Touch",R2:R16) -> 1.55 | F24: =IF(D24<0.3,"⏳ Dormant",IF(D24<1,"🔄 Developing","✅ Mature")) -> ✅ Mature
A25: Taste | B25: =COUNTIF(S2:S16,"Taste") -> 2 | C25: Brainstem | D25: =AVERAGEIF(S2:S16,"Taste",L2:L16) -> 1 | E25: =AVERAGEIF(S2:S16,"Taste",R2:R16) -> 1.65 | F25: =IF(D25<0.3,"⏳ Dormant",IF(D25<1,"🔄 Developing","✅ Mature")) -> ✅ Mature
A26: Smell | B26: =COUNTIF(S2:S16,"Smell") -> 2 | C26: Cerebrum | D26: =AVERAGEIF(S2:S16,"Smell",L2:L16) -> 1 | E26: =AVERAGEIF(S2:S16,"Smell",R2:R16) -> 1.55 | F26: =IF(D26<0.3,"⏳ Dormant",IF(D26<1,"🔄 Developing","✅ Mature")) -> ✅ Mature
A27: Balance | B27: =COUNTIF(S2:S16,"Balance") -> 1 | C27: Brainstem | D27: =AVERAGEIF(S2:S16,"Balance",L2:L16) -> 1 | E27: =AVERAGEIF(S2:S16,"Balance",R2:R16) -> 1.7 | F27: =IF(D27<0.3,"⏳ Dormant",IF(D27<1,"🔄 Developing","✅ Mature")) -> ✅ Mature
A29: TOTALS: | B29: =SUM(B22:B27) -> 15 | D29: =AVERAGE(D22:D27) -> 1 | E29: =AVERAGE(E22:E27) -> 1.6416667
A31: 🔗 CROSS-SYSTEM CONNECTIONS
A33: Linked System | B33: Connection Point | C33: Data Shared | D33: Status
A34: DNA Loop Engine | B34: Current Week (B5) | C34: Timing & Growth Factor | D34: 🟢 LINKED
A35: Neural Control | B35: Cerebrum/Brainstem | C35: Signal Pathways | D35: 🟢 LINKED
A36: Anatomy Growth Engine | B36: Sensory Organs (Eyes, Ears, etc.) | C36: Spatial Coordinates | D36: 🟢 LINKED
A37: Respiratory Control | B37: Nasal Cavity, Pharynx | C37: Airway/Smell Connection | D37: 🟢 LINKED
A38: Digestive Control | B38: Mouth, Tongue | C38: Taste/Intake Feedback | D38: 🟢 LINKED

Sheet Adult Anatomy Engine
A1: Name | B1: Category | C1: DNA Code | D1: Domain | E1: Parent | F1: Local X | G1: Local Y | H1: Local Z | I1: Connection Type | J1: Size (cm) | K1: Mass (kg) | L1: Status | M1: Notes
A2: Frontal Bone | B2: Skeleton | C2: SK_FRONTAL | D2: Embodiment | E2: Point 0 | F2: 0 | G2: 0.85 | H2: 0.08 | I2: Suture | J2: 12 | K2: 0.05 | L2: ✅ Mature | M2: Forehead
A3: Parietal Bone (Left) | B3: Skeleton | C3: SK_PAR_L | D3: Embodiment | E3: Frontal Bone | F3: -0.08 | G3: 0.88 | H3: 0 | I3: Suture | J3: 13 | K3: 0.04 | L3: ✅ Mature | M3: Skull top left
A4: Parietal Bone (Right) | B4: Skeleton | C4: SK_PAR_R | D4: Embodiment | E4: Frontal Bone | F4: 0.08 | G4: 0.88 | H4: 0 | I4: Suture | J4: 13 | K4: 0.04 | L4: ✅ Mature | M4: Skull top right
A5: Temporal Bone (Left) | B5: Skeleton | C5: SK_TEMP_L | D5: Embodiment | E5: Parietal Bone (Left) | F5: -0.12 | G5: 0.82 | H5: -0.02 | I5: Suture | J5: 5 | K5: 0.03 | L5: ✅ Mature | M5: Temple left
A6: Temporal Bone (Right) | B6: Skeleton | C6: SK_TEMP_R | D6: Embodiment | E6: Parietal Bone (Right) | F6: 0.12 | G6: 0.82 | H6: -0.02 | I6: Suture | J6: 5 | K6: 0.03 | L6: ✅ Mature | M6: Temple right
A7: Occipital Bone | B7: Skeleton | C7: SK_OCCIPITAL | D7: Embodiment | E7: Point 0 | F7: 0 | G7: 0.8 | H7: -0.08 | I7: Suture | J7: 10 | K7: 0.06 | L7: ✅ Mature | M7: Back of skull
A8: Sphenoid Bone | B8: Skeleton | C8: SK_SPHENOID | D8: Embodiment | E8: Point 0 | F8: 0 | G8: 0.78 | H8: 0.02 | I8: Suture | J8: 8 | K8: 0.02 | L8: ✅ Mature | M8: Skull base
A9: Ethmoid Bone | B9: Skeleton | C9: SK_ETHMOID | D9: Embodiment | E9: Sphenoid Bone | F9: 0 | G9: 0.8 | H9: 0.04 | I9: Suture | J9: 4 | K9: 0.01 | L9: ✅ Mature | M9: Nasal bridge
A10: Mandible | B10: Skeleton | C10: SK_MANDIBLE | D10: Embodiment | E10: Temporal Bone (Left) | F10: 0 | G10: 0.68 | H10: 0.12 | I10: TMJ | J10: 12 | K10: 0.08 | L10: ✅ Mature | M10: Jaw bone
A11: Maxilla (Left) | B11: Skeleton | C11: SK_MAX_L | D11: Embodiment | E11: Frontal Bone | F11: -0.03 | G11: 0.72 | H11: 0.1 | I11: Suture | J11: 5 | K11: 0.02 | L11: ✅ Mature | M11: Upper jaw left
A12: Maxilla (Right) | B12: Skeleton | C12: SK_MAX_R | D12: Embodiment | E12: Frontal Bone | F12: 0.03 | G12: 0.72 | H12: 0.1 | I12: Suture | J12: 5 | K12: 0.02 | L12: ✅ Mature | M12: Upper jaw right
A13: Cervical Vertebrae (C1-C7) | B13: Skeleton | C13: SK_CERV | D13: Embodiment | E13: Point 0 | F13: 0 | G13: 0.6 | H13: -0.04 | I13: Intervertebral | J13: 12 | K13: 0.1 | L13: ✅ Mature | M13: Neck vertebrae
... A150: Deltoid Ligament | B150: Connective | C150: CT_DELTOID_LIG | D150: Embodiment | E150: Tarsals (Left) | F150: -0.13 | G150: -0.68 | H150: 0 | I150: Ligament | J150: 5 | K150: 0.01 | L150: ✅ Mature | M150: Ankle medial support
A153: 🧭 POINT 0 — ADULT REFERENCE FRAME
A155: Parameter | B155: Value | C155: Unit | E155: 📐 COORDINATE SYSTEM
A156: X₀ (Horizontal) | B156: 0 | C156: m | E156: Axis | F156: Direction
A157: Y₀ (Vertical) | B157: 0 | C157: m | E157: {=+X} -> #NAME? | F157: Right
A158: Z₀ (Depth) | B158: 0 | C158: m | E158: {=-X} -> #NAME? | F158: Left
E159: {=+Y} -> #NAME? | F159: Up (Head)
A160: Reference Point: | B160: Pelvis Centre | E160: {=-Y} -> #NAME? | F160: Down (Feet)
A161: Reference Height: | B161: 175 | C161: cm | E161: {=+Z} -> #NAME? | F161: Forward (Anterior)
A162: Reference Mass: | B162: 70 | C162: kg | E162: {=-Z} -> #NAME? | F162: Backward (Posterior)
A164: 🔗 ALL COORDINATES ARE RELATIVE TO POINT 0 (PELVIS CENTRE)
A166: 📊 ADULT ANATOMY SUMMARY
A168: Category | B168: Count | C168: Total Mass (kg) | E168: Domain | F168: Components
A169: Skeleton | B169: =COUNTIF(AdultAnatomyEngine[Category],"Skeleton") -> 51 | C169: =SUMIF(AdultAnatomyEngine[Category],"Skeleton",AdultAnatomyEngine[Mass (kg)]) -> 5.32 | E169: Embodiment | F169: =COUNTIF(AdultAnatomyEngine[Domain],"Embodiment") -> 86
A170: Organ | B170: =COUNTIF(AdultAnatomyEngine[Category],"Organ") -> 32 | C170: =SUMIF(AdultAnatomyEngine[Category],"Organ",AdultAnatomyEngine[Mass (kg)]) -> 11.2057 | E170: Neural Processing | F170: =COUNTIF(AdultAnatomyEngine[Domain],"Neural Processing") -> 4
A171: Muscle | B171: =COUNTIF(AdultAnatomyEngine[Category],"Muscle") -> 47 | C171: =SUMIF(AdultAnatomyEngine[Category],"Muscle",AdultAnatomyEngine[Mass (kg)]) -> 11.373 | E171: Motor Control | F171: =COUNTIF(AdultAnatomyEngine[Domain],"Motor Control") -> 48
A172: Connective | B172: =COUNTIF(AdultAnatomyEngine[Category],"Connective") -> 19 | C172: =SUMIF(AdultAnatomyEngine[Category],"Connective",AdultAnatomyEngine[Mass (kg)]) -> 0.318 | E172: Endocrine | F172: =COUNTIF(AdultAnatomyEngine[Domain],"Endocrine") -> 6
E173: Sensing | F173: =COUNTIF(AdultAnatomyEngine[Domain],"Sensing") -> 5
A174: TOTAL | B174: =SUM(B170:B173) -> 98 | C174: =SUM(C170:C173) -> 22.8967
A176: 🎯 CONNECTION TYPES
A178: Type | B178: Count | E178: Type | F178: Count
A179: Ball-Socket | B179: =COUNTIF(AdultAnatomyEngine[Connection Type],"Ball-Socket") -> 4 | E179: Tendon | F179: =COUNTIF(AdultAnatomyEngine[Connection Type],"Tendon") -> 52
A180: Hinge | B180: =COUNTIF(AdultAnatomyEngine[Connection Type],"Hinge") -> 8 | E180: Ligament | F180: =COUNTIF(AdultAnatomyEngine[Connection Type],"Ligament") -> 20
A181: Pivot | B181: =COUNTIF(AdultAnatomyEngine[Connection Type],"Pivot") -> 2 | E181: Suture | F181: =COUNTIF(AdultAnatomyEngine[Connection Type],"Suture") -> 10
A182: Gliding | B182: =COUNTIF(AdultAnatomyEngine[Connection Type],"Gliding") -> 4 | E182: Suspended | F182: =COUNTIF(AdultAnatomyEngine[Connection Type],"Suspended") -> 7
A183: Condyloid | B183: =COUNTIF(AdultAnatomyEngine[Connection Type],"Condyloid") -> 4 | E183: Cartilaginous | F183: =COUNTIF(AdultAnatomyEngine[Connection Type],"Cartilaginous") -> 3
A186: 🔗 CROSS-SYSTEM CONNECTIONS
...

Sheet Infant Development
